<?xml version="1.0"?>
<robot name="GP7">
    <!-- link list -->
    <link name="base_link">
        <visual>
            <geometry>
                <mesh filename="/home/zhongqi/Documents/workspace/drake_cfs_lib/script/environment_description/gp7/meshes/visual/gp7_base_link.obj"/>
            </geometry>
            <material name="Endeffector_material">
                <color rgba="0.129411765 0.149019608 0.749019608 1.0" />
            </material>
        </visual>
        <collision>
            <geometry>
                <mesh filename="/home/zhongqi/Documents/workspace/drake_cfs_lib/script/environment_description/gp7/meshes/collision/gp7_base_link.obj"/>
            </geometry>
        </collision>
    </link>
    <link name="link_1_s">
        <visual>
            <geometry>
                <mesh filename="/home/zhongqi/Documents/workspace/drake_cfs_lib/script/environment_description/gp7/meshes/visual/gp7_link_1_s.obj"/>
            </geometry>
            <material name="Endeffector_material">
                <color rgba="0.129411765 0.149019608 0.749019608 1.0" />
            </material>
        </visual>
        <!-- <collision>
            <geometry>
                <mesh filename="/home/zhongqi/Documents/workspace/drake_cfs_lib/script/environment_description/gp7/meshes/collision/gp7_link_1_s.obj"/>
            </geometry>
        </collision> -->
    </link>
    <link name="link_2_l">
        <visual>
            <geometry>
                <mesh filename="/home/zhongqi/Documents/workspace/drake_cfs_lib/script/environment_description/gp7/meshes/visual/gp7_link_2_l.obj"/>
            </geometry>
            <material name="Endeffector_material">
                <color rgba="0.129411765 0.149019608 0.749019608 1.0" />
            </material>
        </visual>
        <!-- <collision>
            <geometry>
                <mesh filename="/home/zhongqi/Documents/workspace/drake_cfs_lib/script/environment_description/gp7/meshes/collision/gp7_link_2_l.obj"/>
            </geometry>
        </collision> -->
    </link>
    <link name="link_3_u">
        <visual>
            <geometry>
                <mesh filename="/home/zhongqi/Documents/workspace/drake_cfs_lib/script/environment_description/gp7/meshes/visual/gp7_link_3_u.obj"/>
            </geometry>
            <material name="Endeffector_material">
                <color rgba="0.129411765 0.149019608 0.749019608 1.0" />
            </material>
        </visual>
        <!-- <collision>
            <geometry>
                <mesh filename="/home/zhongqi/Documents/workspace/drake_cfs_lib/script/environment_description/gp7/meshes/collision/gp7_link_3_u.obj"/>
            </geometry>
        </collision> -->
    </link>
    <link name="link_4_r">
        <visual>
            <geometry>
                <mesh filename="/home/zhongqi/Documents/workspace/drake_cfs_lib/script/environment_description/gp7/meshes/visual/gp7_link_4_r.obj"/>
            </geometry>
            <material name="Endeffector_material">
                <color rgba="0.129411765 0.149019608 0.749019608 1.0" />
            </material>
        </visual>
        <!-- <collision>
            <geometry>
                <mesh filename="/home/zhongqi/Documents/workspace/drake_cfs_lib/script/environment_description/gp7/meshes/collision/gp7_link_4_r.obj"/>
            </geometry>
        </collision> -->
    </link>
    <link name="link_5_b">
        <visual>
            <geometry>
                <mesh filename="/home/zhongqi/Documents/workspace/drake_cfs_lib/script/environment_description/gp7/meshes/visual/gp7_link_5_b.obj"/>
            </geometry>
            <material name="Endeffector_material">
                <color rgba="0.129411765 0.149019608 0.749019608 1.0" />
            </material>
        </visual>
        <!-- <collision>
            <geometry>
                <mesh filename="/home/zhongqi/Documents/workspace/drake_cfs_lib/script/environment_description/gp7/meshes/collision/gp7_link_5_b.obj"/>
            </geometry>
        </collision> -->
    </link>
    <link name="link_6_t">
        <visual>
            <geometry>
                <mesh filename="/home/zhongqi/Documents/workspace/drake_cfs_lib/script/environment_description/gp7/meshes/visual/gp7_link_6_t.obj"/>
            </geometry>
            <material name="Endeffector_material">
                <color rgba="0.129411765 0.149019608 0.749019608 1.0" />
            </material>
        </visual>
        <collision>
            <geometry>
                <mesh filename="/home/zhongqi/Documents/workspace/drake_cfs_lib/script/environment_description/gp7/meshes/collision/gp7_link_6_t.obj"/>
            </geometry>
        </collision>
    </link>
    <link name="tool0">
        <visual name="Endeffector">
            <origin rpy="0.000000 0.000000 0.000000" xyz="0.000000 0.000000 0.000000" />
            <geometry>
                <sphere radius="0.02"/>
            </geometry>
            <material name="Endeffector_material">
                <color rgba="0.129411765 0.149019608 0.749019608 1.0" />
            </material>
        </visual>
    </link>

    <!-- joint list -->
    <joint name="joint_1_s" type="revolute">
        <parent link="base_link"/>
        <child link="link_1_s"/>
        <origin xyz="0 0 0.330" rpy="0 0 0" />
        <axis xyz="0 0 1" />
        <limit lower="-2.9670" upper="2.9670" effort="212.66" velocity="6.5448"/>
    </joint>
    <joint name="joint_2_l" type="revolute">
        <parent link="link_1_s"/>
        <child link="link_2_l"/>
        <origin xyz="0.040 0 0" rpy="0 0 0" />
        <axis xyz="0 1 0" />
        <limit lower="-1.1344" upper="2.5307" effort="205.80" velocity="5.4977"/>
    </joint>
    <joint name="joint_3_u" type="revolute">
        <parent link="link_2_l"/>
        <child link="link_3_u"/>
        <origin xyz="0 0 0.445" rpy="0 0 0" />
        <axis xyz="0 -1 0" />
        <limit lower="-1.2217" upper="3.3161" effort="106.82" velocity="7.1558"/>
    </joint>
    <joint name="joint_4_r" type="revolute">
        <parent link="link_3_u"/>
        <child link="link_4_r"/>
        <origin xyz="0.440 0 0.040" rpy="0 0 0" />
        <axis xyz="-1 0 0" />
        <limit lower="-3.3161" upper="3.3161" effort="55.86" velocity="9.5993"/>
    </joint>
    <joint name="joint_5_b" type="revolute">
        <parent link="link_4_r"/>
        <child link="link_5_b"/>
        <origin xyz="0 0 0" rpy="0 0 0" />
        <axis xyz="0 -1 0" />
        <limit lower="-2.3561" upper="2.3561" effort="32.68" velocity="9.5993"/>
    </joint>
    <joint name="joint_6_t" type="revolute">
        <parent link="link_5_b"/>
        <child link="link_6_t"/>
        <origin xyz="0 0 0" rpy="0 0 0" />
        <axis xyz="-1 0 0" />
        <limit lower="-6.2944" upper="6.2944" effort="22.54" velocity="17.4845"/>
    </joint>
    <joint name="joint_6_t-endeffector" type="fixed">
        <origin rpy="0.000000 0.000000 0.000000" xyz="0.1 0.0 0.0" />
        <parent link="link_6_t"/>
        <child link="tool0"/>
    </joint>
    <!-- end of joint list -->

    <!-- ROS base_link to Robot Manufacturer World Coordinates transform -->
    <!-- <link name="base" />
    <joint name="base_link-base" type="fixed">
        <origin xyz="0 0 0.330" rpy="0 0 0"/>
        <parent link="base_link"/>
        <child link="base"/>
    </joint> -->

    <!-- <link name="world" />
    <joint name="world-base_link" type="floating">
        <origin xyz="0 0 0" rpy="0 0 0"/>
        <parent link="world"/>
        <child link="base_link"/>
    </joint> -->
</robot>
